Workbook

Sheet Sheet1
B2: PJSC POLYUS | X2: QUARTERLY | CG2: SEMI-ANNUAL
B4: OPERATING RESULTS* | F4: 2007 | G4: 2008 | H4: 2009 | I4: 2010 | J4: 2011 | K4: 2012 | L4: 2013 | M4: 2014 | N4: 2015 | O4: 2016 | P4: 2017 | Q4: 2018 | R4: 2019 | S4: 2020 | T4: 2021 | U4: 2022 | V4: 2023 | W4: 2024 | X4: DATA | Y4: 1Q'07 | Z4: 2Q'07 | AA4: 3Q'07 | AB4: 4Q'07 | AC4: 1Q'08 | AD4: 2Q'08 | AE4: 3Q'08 | AF4: 4Q'08 | AG4: 1Q'09 | AH4: 2Q'09 | AI4: 3Q'09 | AJ4: 4Q'09 | AK4: 1Q'10 | AL4: 2Q'10 | AM4: 3Q'10 | AN4: 4Q'10 | AO4: 1Q'11 | AP4: 2Q'11 | AQ4: 3Q'11 | AR4: 4Q'11 | AS4: 1Q'12 | AT4: 2Q'12 | AU4: 3Q'12 | AV4: 4Q'12 | AW4: 1Q'13 | AX4: 2Q'13 | AY4: 3Q'13 | AZ4: 4Q'13 | BA4: 1Q'14 | BB4: 2Q'14 | BC4: 3Q'14 | BD4: 4Q'14 | BE4: 1Q'15 | BF4: 2Q'15 | BG4: 3Q'15 | BH4: 4Q'15 | BI4: 1Q'16 | BJ4: 2Q'16 | BK4: 3Q'16 | BL4: 4Q'16 | BM4: 1Q'17 | BN4: 2Q'17 | BO4: 3Q'17 | BP4: 4Q'17 | BQ4: 1Q'18 | BR4: 2Q'18 | BS4: 3Q'18 | BT4: 4Q'18 | BU4: 1Q'19 | BV4: 2Q'19 | BW4: 3Q'19 | BX4: 4Q'19 | BY4: 1Q'20 | BZ4: 2Q'20 | CA4: 3Q'20 | CB4: 4Q'20 | CC4: 1Q'21 | CD4: 2Q'21 | CE4: 3Q'21 | CF4: 4Q'21 | CG4: DATA | CH4: 1H'21 | CI4: 2H'21 | CJ4: 1H'22 | CK4: 2H'22 | CL4: 1H'23 | CM4: 2H'23 | CN4: 1H'24 | CO4: 2H'24 | CP4: 1H'25
Y5: 39172 | Z5: 39263 | AA5: 39355 | AB5: 39447 | AC5: 39538 | AD5: 39629 | AE5: 39721 | AF5: 39813 | AG5: 39903 | AH5: 39994 | AI5: 40086 | AJ5: 40178 | AK5: 40268 | AL5: 40359 | AM5: 40451 | AN5: 40543 | AO5: 40633 | AP5: 40724 | AQ5: 40816 | AR5: 40908 | AS5: 40999 | AT5: 41090 | AU5: 41182 | AV5: 41274 | AW5: 41364 | AX5: 41455 | AY5: 41547 | AZ5: 41639 | BA5: 41729 | BB5: 41820 | BC5: 41912 | BD5: 42004 | BE5: 42094 | BF5: 42185 | BG5: 42277 | BH5: 42369 | BI5: 42460 | BJ5: 42551 | BK5: 42643 | BL5: 42735 | BM5: 42825 | BN5: 42916
G6: 2008 | H6: 2009 | I6: 2010 | J6: 2011 | K6: 2012 | L6: 2013 | M6: 2014 | N6: 2015 | O6: 2016 | Y6: 2007 | Z6: 2007 | AA6: 2007 | AB6: 2007 | AC6: 2008 | AD6: 2008 | AE6: 2008 | AF6: 2008 | AG6: 2009 | AH6: 2009 | AI6: 2009 | AJ6: 2009 | AK6: 2010 | AL6: 2010 | AM6: 2010 | AN6: 2010 | AO6: 2011 | AP6: 2011 | AQ6: 2011 | AR6: 2011 | AS6: 2012 | AT6: 2012 | AU6: 2012 | AV6: 2012 | AW6: 2013 | AX6: 2013 | AY6: 2013 | AZ6: 2013 | BA6: 2014 | BB6: 2014 | BC6: 2014 | BD6: 2014 | BE6: 2015 | BF6: 2015 | BG6: 2015 | BH6: 2015 | BI6: 2016 | BJ6: 2016 | BK6: 2016 | BL6: 2016 | BM6: 2017 | BN6: 2017
G7: 4 | H7: 4 | I7: 4 | J7: 4 | K7: 4 | L7: 4 | M7: 4 | N7: 4 | O7: 4 | Y7: 1 | Z7: 2 | AA7: 3 | AB7: 4 | AC7: 1 | AD7: 2 | AE7: 3 | AF7: 4 | AG7: 1 | AH7: 2 | AI7: 3 | AJ7: 4 | AK7: 1 | AL7: 2 | AM7: 3 | AN7: 4 | AO7: 1 | AP7: 2 | AQ7: 3 | AR7: 4 | AS7: 1 | AT7: 2 | AU7: 3 | AV7: 4 | AW7: 1 | AX7: 2 | AY7: 3 | AZ7: 4 | BA7: 1 | BB7: 2 | BC7: 3 | BD7: 4 | BE7: 1 | BF7: 2 | BG7: 3 | BH7: 4 | BI7: 1 | BJ7: 2 | BK7: 3 | BL7: 4 | BM7: 1 | BN7: 2
B10: CONSOLIDATED OPERATING RESULTS
B12: Mining
B13: Total rock moved | C13: 000 m3 | F13: 49474 | G13: 50759.2 | H13: 48477.1 | I13: 55609.719 | J13: 53466.339 | K13: 66703.426 | L13: 66351.174 | M13: 71238.621 | N13: 64505.2 | O13: 58073.24 | P13: 88417.645 | Q13: 116987.17 | R13: 127952.24 | S13: 124232.62 | T13: 136429.92 | U13: 144207 | V13: 139052 | W13: 183549 | Y13: 11240.8 | Z13: 11979.8 | AA13: 13172.6 | AB13: 13080.8 | AC13: 12297.8 | AD13: 12126.3 | AE13: 13092.3 | AF13: 13242.8 | AG13: 12336.1 | AH13: 10996.8 | AI13: 11060.4 | AJ13: 14083.8 | AK13: 12672.7 | AL13: 14100.84 | AM13: 14789.399 | AN13: 14046.78 | AO13: 12839.44 | AP13: 13033.499 | AQ13: 13535.6 | AR13: 14057.8 | AS13: 16052.224 | AT13: 16420 | AU13: 16955.787 | AV13: 17275.415 | AW13: 16764.84 | AX13: 15985.079 | AY13: 16653.765 | AZ13: 16947.49 | BA13: 16828.727 | BB13: 17943.646 | BC13: 19077.702 | BD13: 17388.546 | BE13: 16111.269 | BF13: 15897.364 | BG13: 16447.244 | BH13: 16049.324 | BI13: 15147.421 | BJ13: 13286.463 | BK13: 14608.546 | BL13: 15030.809 | BM13: 18577.86 | BN13: 20675.019 | BO13: 24435.882 | BP13: 24728.884 | BQ13: 26133.841 | BR13: 28319.993 | BS13: 31239.5 | BT13: 31293.839 | BU13: 30210.605 | BV13: 31582.96 | BW13: 33738.058 | BX13: 32420.617 | BY13: 32372.793 | BZ13: 28909.286 | CA13: 32210.497 | CB13: 30741 | CC13: 31587.145 | CD13: 33120.136 | CE13: 35728.513 | CF13: 35994.131 | CH13: 64707 | CI13: 71723 | CJ13: 73981 | CK13: 70226 | CL13: 68494 | CM13: 70558 | CN13: 81420 | CO13: 102129 | CP13: 108064
B14: Stripping | C14: 000 m3 | F14: 44255.4 | G14: 47543.4 | H14: 40990.8 | I14: 46878.11 | J14: 45316.98 | K14: 57255.939 | L14: 54551.748 | M14: 59447.684 | N14: 55628.078 | O14: 46326.125 | P14: 73419.891 | Q14: 99480.959 | R14: 101563.48 | S14: 96126.834 | T14: 109711.51 | U14: 119017.9 | V14: 106997.49 | W14: 144676.78 | Y14: 9493.2 | Z14: 10798.2 | AA14: 11986.7 | AB14: 11977.3 | AC14: 11517.8 | AD14: 11304.9 | AE14: 12215.2 | AF14: 12505.5 | AG14: 11029.6 | AH14: 9176.5 | AI14: 8844 | AJ14: 11940.7 | AK14: 10508.5 | AL14: 11879.9 | AM14: 12714.07 | AN14: 11775.64 | AO14: 10633.84 | AP14: 10970.28 | AQ14: 11678.23 | AR14: 12034.63 | AS14: 13352.909 | AT14: 13959.84 | AU14: 14725.86 | AV14: 15217.33 | AW14: 14186.86 | AX14: 12906.747 | AY14: 13532.922 | AZ14: 13925.22 | BA14: 12986.471 | BB14: 14632.106 | BC14: 16547.34 | BD14: 15281.767 | BE14: 14084.787 | BF14: 13594.275 | BG14: 14237.598 | BH14: 13711.418 | BI14: 12435.395 | BJ14: 10534.153 | BK14: 11892.836 | BL14: 11463.741 | BM14: 15169.448 | BN14: 17003.116 | BO14: 20478.305 | BP14: 20769.021 | BQ14: 22583.242 | BR14: 24443.357 | BS14: 25988.519 | BT14: 26465.841 | BU14: 24663.929 | BV14: 25231.141 | BW14: 26703.959 | BX14: 24964.445 | BY14: 25251.044 | BZ14: 21972.517 | CA14: 24879.049 | CB14: 24040.997 | CC14: 25065.507 | CD14: 26351.385 | CE14: 28957.238 | CF14: 29337.378 | CH14: 51417 | CI14: 58295 | CJ14: 62481.393 | CK14: 56536.504 | CL14: 54141.279 | CM14: 52856.206 | CN14: 61737 | CO14: 82939.387 | CP14: 91506
B15: Stripping ratio | C15: m3/t | F15: 4.7195188 | G15: 7.2307154 | H15: 2.282275 | I15: 2.171984 | J15: 2.2427523 | K15: 2.432232 | L15: 1.5976795 | M15: 1.9895471 | N15: 2.5271153 | O15: 1.5607303 | P15: 1.9418115 | Q15: 2.3221062 | R15: 1.5366188 | S15: 1.3509471 | T15: 1.6296815 | U15: 1.9 | V15: 1.3 | W15: 1.5 | Y15: 2.5836055 | Z15: 5.4202389 | AA15: 5.7509476 | AB15: 7.3652072 | AC15: 7.3305754 | AD15: 6.5937008 | AE15: 6.6405001 | AF15: 8.6244828 | AG15: 3.7230717 | AH15: 2.1362557 | AI15: 1.6338143 | AJ15: 2.2575199 | AK15: 1.9695805 | AL15: 2.1765992 | AM15: 2.4628131 | AN15: 2.0926082 | AO15: 1.9238029 | AP15: 2.1446257 | AQ15: 2.5501956 | AR15: 2.4147165 | AS15: 1.9730146 | AT15: 2.2648006 | AU15: 2.6415432 | AV15: 3.0228043 | AW15: 2.0137 | AX15: 1.4776626 | AY15: 1.5048463 | AZ15: 1.485875 | BA15: 1.3169155 | BB15: 1.7298207 | BC15: 2.6079088 | BD15: 2.9303889 | BE15: 2.807955 | BF15: 2.3544559 | BG15: 2.6189812 | BH15: 2.369639 | BI15: 1.8201588 | BJ15: 1.5161949 | BK15: 1.7443807 | BL15: 1.2618672 | BM15: 1.759813 | BN15: 1.8461579 | BO15: 2.0654897 | BP15: 2.0634894 | BQ15: 2.5601571 | BR15: 2.6234167 | BS15: 2.0508307 | BT15: 2.1999454 | BU15: 1.7712052 | BV15: 1.6110861 | BW15: 1.5279369 | BX15: 1.3131579 | BY15: 1.3854201 | BZ15: 1.2653916 | CA15: 1.3622617 | CB15: 1.3895227 | CC15: 1.5064184 | CD15: 1.5476812 | CE15: 1.7208735 | CF15: 1.7433396 | CH15: 1.5 | CI15: 1.7 | CJ15: 2.2 | CK15: 1.7 | CL15: 1.5 | CM15: 1.2 | CN15: 1.2 | CO15: 1.7 | CP15: 2.3
B16: Ore mined | C16: kT | F16: 9377.1 | G16: 6575.2 | H16: 17960.5 | I16: 21583.083 | J16: 20205.968 | K16: 23540.492 | L16: 34144.363 | M16: 29880.009 | N16: 22012.481 | O16: 29682.338 | P16: 37810 | Q16: 42840.83 | R16: 66095.427 | S16: 71155.144 | T16: 67320.827 | U16: 62333 | V16: 81757 | W16: 98026 | Y16: 3674.4 | Z16: 1992.2 | AA16: 2084.3 | AB16: 1626.2 | AC16: 1571.2 | AD16: 1714.5 | AE16: 1839.5 | AF16: 1450 | AG16: 2962.5 | AH16: 4295.6 | AI16: 5413.1 | AJ16: 5289.3 | AK16: 5335.4 | AL16: 5458.01 | AM16: 5162.4178 | AN16: 5627.255 | AO16: 5527.51 | AP16: 5115.2423 | AQ16: 4579.3468 | AR16: 4983.8687 | AS16: 6767.77 | AT16: 6163.8275 | AU16: 5574.7186 | AV16: 5034.1764 | AW16: 7045.1706 | AX16: 8734.5694 | AY16: 8992.8929 | AZ16: 9371.7302 | BA16: 9861.279 | BB16: 8458.741 | BC16: 6345.0609 | BD16: 5214.9279 | BE16: 5016.03 | BF16: 5773.85 | BG16: 5436.3115 | BH16: 5786.2898 | BI16: 6832.0386 | BJ16: 6947.7562 | BK16: 6817.7986 | BL16: 9084.7446 | BM16: 8619.9207 | BN16: 9210.0008 | BO16: 9914.5039 | BP16: 10065 | BQ16: 8821.0377 | BR16: 9317.3747 | BS16: 12673 | BT16: 12030.227 | BU16: 13946.34 | BV16: 15660.952 | BW16: 17477.135 | BX16: 19011 | BY16: 18226.272 | BZ16: 17364.203 | CA16: 18264 | CB16: 17301 | CC16: 16639.141 | CD16: 17027 | CE16: 16827.058 | CF16: 16828.264 | CH16: 33666 | CI16: 33655 | CJ16: 28149 | CK16: 34184 | CL16: 36471 | CM16: 45286 | CN16: 50210 | CO16: 47816 | CP16: 38945
B17: Average grade in ore mined | C17: g/t | F17: 4.169786 | G17: 1.7677485 | H17: 2.5018847 | I17: 2.4118227 | J17: 2.4247284 | K17: 2.3677328 | L17: 2.3800896 | M17: 2.0131631 | N17: 1.8714069 | O17: 2.3559662 | P17: 2.4553028 | Q17: 2.3780405 | R17: 1.9469623 | S17: 1.7655726 | T17: 1.6332533 | U17: 1.6490493 | V17: 1.9635648 | W17: 1.5318535 | Y17: 5.7611311 | Z17: 3.4759562 | AA17: 3.2726575 | AB17: 2.5739761 | AC17: 1.9044679 | AD17: 1.8424614 | AE17: 1.6742049 | AF17: 1.649931 | AG17: 1.9494346 | AH17: 2.2961402 | AI17: 2.858787 | AJ17: 2.6131435 | AK17: 2.5403213 | AL17: 2.2832983 | AM17: 2.3209962 | AN17: 2.4979716 | AO17: 2.4226242 | AP17: 2.3207251 | AQ17: 2.4187264 | AR17: 2.5393219 | AS17: 2.473379 | AT17: 2.4117756 | AU17: 2.2935633 | AV17: 2.2539133 | AW17: 2.2793029 | AX17: 2.474296 | AY17: 2.3826513 | AZ17: 2.3655962 | BA17: 2.3149365 | BB17: 2.0782288 | BC17: 1.7140387 | BD17: 1.7009284 | BE17: 1.8444524 | BF17: 1.8872743 | BG17: 1.815472 | BH17: 1.9314917 | BI17: 2.0802787 | BJ17: 2.3108874 | BK17: 2.3430781 | BL17: 2.6074397 | BM17: 2.5365385 | BN17: 2.4930213 | BO17: 2.4438756 | BP17: 2.3611575 | BQ17: 2.4330593 | BR17: 2.4380291 | BS17: 2.3126105 | BT17: 2.360159 | BU17: 2.0599898 | BV17: 2.1072902 | BW17: 1.9001312 | BX17: 1.7750233 | BY17: 1.7021282 | BZ17: 1.8670152 | CA17: 1.7844092 | CB17: 1.7087818 | CC17: 1.714072 | CD17: 1.7834139 | CE17: 1.4735217 | CF17: 1.5611348 | CH17: 1.75 | CI17: 1.52 | CJ17: 1.42 | CK17: 1.8364774 | CL17: 2.04 | CM17: 1.8995414 | CN17: 1.76 | CO17: 1.2956892 | CP17: 1.2
B19: Processing
B20: Ore processed | C20: kT | F20: 10518.569 | G20: 10814.122 | H20: 13930.592 | I20: 18230.309 | J20: 20160.756 | K20: 21757.982 | L20: 22481 | M20: 23743 | N20: 24823 | O20: 26445 | P20: 28663.272 | Q20: 38024.578 | R20: 44078.439 | S20: 45113 | T20: 47895.11 | U20: 48319 | V20: 48894 | W20: 50527 | Y20: 2226.6816 | Z20: 2386.865 | AA20: 3071.4328 | AB20: 2833.5897 | AC20: 2143.549 | AD20: 2850.262 | AE20: 2694.541 | AF20: 3125.77 | AG20: 3319.5813 | AH20: 3318.205 | AI20: 3402.001 | AJ20: 3890.805 | AK20: 3848.13 | AL20: 4645.6 | AM20: 4807.34 | AN20: 4929.239 | AO20: 5081.621 | AP20: 4806.623 | AQ20: 5191.855 | AR20: 5080.657 | AS20: 5248.8818 | AT20: 5141.101 | AU20: 5590.378 | AV20: 5777.621 | AW20: 5280 | AX20: 5680 | AY20: 5776 | AZ20: 5745 | BA20: 5633 | BB20: 6016 | BC20: 6053 | BD20: 6041 | BE20: 5978 | BF20: 6143 | BG20: 6322 | BH20: 6380 | BI20: 6396 | BJ20: 6535 | BK20: 6521 | BL20: 6993 | BM20: 6630 | BN20: 6925 | BO20: 7299.2724 | BP20: 7809 | BQ20: 8491.7653 | BR20: 9872 | BS20: 10382 | BT20: 9278.7121 | BU20: 10283.953 | BV20: 10900.821 | BW20: 11366.088 | BX20: 11527 | BY20: 10698.374 | BZ20: 11753 | CA20: 12224 | CB20: 10438 | CC20: 11126.002 | CD20: 12169 | CE20: 12722 | CF20: 11878 | CH20: 23295 | CI20: 24600 | CJ20: 23777 | CK20: 24542 | CL20: 23591 | CM20: 25303 | CN20: 24815 | CO20: 25712 | CP20: 25342
B21: Average grade in ore processed | C21: g/t | F21: 3.6381165 | G21: 3.7090189 | H21: 3.1589391 | I21: 2.6151055 | J21: 2.4918542 | K21: 2.4753478 | L21: 2.4911036 | M21: 2.51412 | N21: 2.428159 | O21: 2.5402635 | P21: 2.698494 | Q21: 2.404956 | R21: 2.3602493 | S21: 2.249944 | T21: 2.12 | U21: 1.97 | V21: 2.26 | W21: 2.1900393 | Y21: 3.411417 | Z21: 3.5927865 | AA21: 3.671789 | AB21: 3.8179454 | AC21: 3.3743623 | AD21: 4.6143915 | AE21: 3.450402 | AF21: 3.3358813 | AG21: 3.0527334 | AH21: 3.1424766 | AI21: 3.676075 | AJ21: 2.8114242 | AK21: 2.5530466 | AL21: 2.5755923 | AM21: 2.6161662 | AN21: 2.6997583 | AO21: 2.4932009 | AP21: 2.4192634 | AQ21: 2.4601472 | AR21: 2.5915835 | AS21: 2.4838084 | AT21: 2.5099231 | AU21: 2.4183859 | AV21: 2.4920113 | AW21: 2.4774749 | AX21: 2.472836 | AY21: 2.5444179 | AZ21: 2.4680881 | BA21: 2.4669507 | BB21: 2.5103353 | BC21: 2.5022045 | BD21: 2.573812 | BE21: 2.4313944 | BF21: 2.5325774 | BG21: 2.3693281 | BH21: 2.3828841 | BI21: 2.3902954 | BJ21: 2.3564058 | BK21: 2.5760735 | BL21: 2.8158516 | BM21: 2.5778287 | BN21: 2.6975835 | BO21: 2.8445642 | BP21: 2.6521273 | BQ21: 2.5206099 | BR21: 2.3668405 | BS21: 2.32 | BT21: 2.4300066 | BU21: 2.4108559 | BV21: 2.3593021 | BW21: 2.2995297 | BX21: 2.3997457 | BY21: 2.1996022 | BZ21: 2.24 | CA21: 2.25 | CB21: 2.3052993 | CC21: 2.1778314 | CD21: 2.1 | CE21: 2.1 | CF21: 2.12 | CH21: 2.14 | CI21: 2.11 | CJ21: 1.86 | CK21: 2.07 | CL21: 2.31 | CM21: 2.22 | CN21: 2.18 | CO21: 2.2039884 | CP21: 1.9
B22: Recovery | C22: % | F22: 0.84677869 | G22: 0.82287174 | H22: 0.74946314 | I22: 0.71883009 | J22: 0.76104718 | K22: 0.78543865 | L22: 0.78992988 | M22: 0.81017695 | N22: 0.83713884 | O22: 0.83886561 | P22: 0.834 | Q22: 0.808 | R22: 0.823 | S22: 0.83751877 | T22: 0.827 | U22: 0.818 | V22: 0.83 | W22: 0.842 | Y22: 0.88739155 | Z22: 0.8799866 | AA22: 0.82707102 | AB22: 0.81006945 | AC22: 0.77034386 | AD22: 0.85182169 | AE22: 0.82717298 | AF22: 0.82613108 | AG22: 0.78620145 | AH22: 0.747825 | AI22: 0.77439939 | AJ22: 0.68540599 | AK22: 0.66900775 | AL22: 0.70541011 | AM22: 0.74750146 | AN22: 0.73676721 | AO22: 0.76378615 | AP22: 0.7826639 | AQ22: 0.735753 | AR22: 0.76132582 | AS22: 0.78699789 | AT22: 0.81514248 | AU22: 0.76328692 | AV22: 0.77917219 | AW22: 0.78538079 | AX22: 0.79236407 | AY22: 0.78360431 | AZ22: 0.79827176 | BA22: 0.79981049 | BB22: 0.80895623 | BC22: 0.81330927 | BD22: 0.81757641 | BE22: 0.82618322 | BF22: 0.83267609 | BG22: 0.85100815 | BH22: 0.83851498 | BI22: 0.84043301 | BJ22: 0.84217616 | BK22: 0.84327287 | BL22: 0.83129991 | BM22: 0.83282921 | BN22: 0.83938412 | BO22: 0.838 | BP22: 0.827 | BQ22: 0.815 | BR22: 0.80623953 | BS22: 0.80575463 | BT22: 0.80610257 | BU22: 0.81406295 | BV22: 0.81790807 | BW22: 0.82145667 | BX22: 0.832 | BY22: 0.83581612 | BZ22: 0.83404487 | CA22: 0.84115123 | CB22: 0.83882127 | CC22: 0.81634021 | CD22: 0.82596919 | CE22: 0.82978908 | CF22: 0.834 | CH22: 0.821 | CI22: 0.832 | CJ22: 0.818 | CK22: 0.818 | CL22: 0.827 | CM22: 0.833 | CN22: 0.836 | CO22: 0.848 | CP22: 0.845
B23: Total Dore gold output1 | C23: koz | F23: 1201.4307 | G23: 1232.4212 | H23: 1227.7918 | I23: 1274.5282 | J23: 1394.1873 | K23: 1564.6152 | L23: 1658.7633 | M23: 1704.9529 | N23: 1767.4358 | O23: 1966.3721 | P23: 2161.8784 | Q23: 2450 | R23: 2846.6 | S23: 2803.5 | T23: 2736.4 | U23: 2568 | V23: 2903.3 | W23: 2935.8 | Y23: 223.92348 | Z23: 287.26619 | AA23: 387.98962 | AB23: 302.2514 | AC23: 202.43133 | AD23: 381.95446 | AE23: 340.82051 | AF23: 307.21491 | AG23: 253.86949 | AH23: 291.73248 | AI23: 422.5744 | AJ23: 259.61543 | AK23: 189.30843 | AL23: 330.22 | AM23: 432.90701 | AN23: 322.09278 | AO23: 298.11709 | AP23: 348.67602 | AQ23: 393.84193 | AR23: 353.55229 | AS23: 334.33246 | AT23: 380.7613 | AU23: 449.88693 | AV23: 399.63451 | AW23: 339.46906 | AX23: 416.84131 | AY23: 474.89998 | AZ23: 427.55298 | BA23: 354.20769 | BB23: 428.84973 | BC23: 484.30045 | BD23: 437.59503 | BE23: 368.9105 | BF23: 457.64523 | BG23: 496.8421 | BH23: 444.03794 | BI23: 398.72558 | BJ23: 466.76741 | BK23: 565.37118 | BL23: 535.50796 | BM23: 439.90439 | BN23: 531.47401 | BO23: 635.8 | BP23: 554.7 | BQ23: 538.77423 | BR23: 627.60486 | BS23: 698.83284 | BT23: 584.81226 | BU23: 656.22098 | BV23: 705.92631 | BW23: 770.17005 | BX23: 714.3 | BY23: 660.17859 | BZ23: 712.37411 | CA23: 770.21289 | CB23: 660.7 | CC23: 614.7 | CD23: 693.4 | CE23: 764.2 | CF23: 664.1 | CH23: 1308.1 | CI23: 1428.3 | CJ23: 1186.2 | CK23: 1381.8 | CL23: 1427.7 | CM23: 1475.6 | CN23: 1481.3 | CO23: 1454.5 | CP23: 1310.5
B24: Total refined gold output2 | C24: koz | F24: 1214.3533 | G24: 1221.6179 | H24: 1230.935 | I24: 1277 | J24: 1381.3371 | K24: 1568.94 | L24: 1649.7 | M24: 1685.5 | N24: 1744.4433 | O24: 1841.4049 | P24: 1990.1602 | Q24: 2183.7963 | R24: 2523.7 | S24: 2568.1 | T24: 2687.6 | U24: 2457.6 | V24: 2482.7 | W24: 2790.6 | Y24: 211.23281 | Z24: 257.46116 | AA24: 408.16837 | AB24: 338.7278 | AC24: 172.2991 | AD24: 391.776 | AE24: 330.96931 | AF24: 326.57351 | AG24: 201.14591 | AH24: 276.84218 | AI24: 444.73877 | AJ24: 308.20811 | AK24: 189.7745 | AL24: 266.2255 | AM24: 419.49688 | AN24: 402.50312 | AO24: 231.79707 | AP24: 321.523 | AQ24: 463.86163 | AR24: 364.15539 | AS24: 302.5 | AT24: 367.1 | AU24: 449.5 | AV24: 449.84 | AW24: 319.9 | AX24: 398.5 | AY24: 466.8 | AZ24: 464.5 | BA24: 330.6 | BB24: 412.6 | BC24: 492.3 | BD24: 450 | BE24: 352.73074 | BF24: 425.29287 | BG24: 503.30227 | BH24: 463.11742 | BI24: 374.97825 | BJ24: 432.4674 | BK24: 515.62785 | BL24: 518.33139 | BM24: 422.02574 | BN24: 454.83447 | BO24: 561.6 | BP24: 551.7 | BQ24: 432.1 | BR24: 538.9 | BS24: 623.8 | BT24: 589.00593 | BU24: 538.01411 | BV24: 615.3 | BW24: 649.7 | BX24: 720.7 | BY24: 533 | BZ24: 646.3 | CA24: 701.1 | CB24: 687.7 | CC24: 569 | CD24: 671.4 | CE24: 763 | CF24: 684.2 | CH24: 1240.4 | CI24: 1447.2 | CJ24: 1063.6 | CK24: 1394 | CL24: 1226.7 | CM24: 1256 | CN24: 1333.4 | CO24: 1457.2 | CP24: 1311.4
B25: Gold contained in concentrate | C25: koz | F25: 0 | G25: 0 | H25: 0 | I25: 0 | J25: 0 | K25: 0 | L25: 2 | M25: 10 | N25: 18.910573 | O25: 126.44112 | P25: 169.99935 | Q25: 256.3 | R25: 317.5 | S25: 198 | T25: 29.8 | U25: 83.7 | V25: 419.5 | W25: 211 | Y25: 0 | Z25: 0 | AA25: 0 | AB25: 0 | AC25: 0 | AD25: 0 | AE25: 0 | AF25: 0 | AG25: 0 | AH25: 0 | AI25: 0 | AJ25: 0 | AK25: 0 | AL25: 0 | AM25: 0 | AN25: 0 | AO25: 0 | AP25: 0 | AQ25: 0 | AR25: 0 | AS25: 0 | AT25: 0 | AU25: 0 | AV25: 0 | AW25: 0 | AX25: 2 | AY25: 0 | AZ25: 0 | BA25: 0 | BB25: 0 | BC25: 0 | BD25: 10 | BE25: 0 | BF25: 5.8636295 | BG25: 10.294919 | BH25: 2.7520247 | BI25: 9.3530728 | BJ25: 22.726259 | BK25: 39.328301 | BL25: 55.033488 | BM25: 28.18051 | BN25: 33.018844 | BO25: 80.7 | BP25: 28.1 | BQ25: 74.4 | BR25: 63.1 | BS25: 67.4 | BT25: 51.4 | BU25: 62.7 | BV25: 68.5 | BW25: 103 | BX25: 83.3 | BY25: 61.9 | BZ25: 44.1 | CA25: 70 | CB25: 22 | CC25: 22.7 | CD25: 0.1 | CE25: 7 | CF25: 0 | CH25: 22.8 | CI25: 7 | CJ25: 4 | CK25: 79.7 | CL25: 221.2 | CM25: 198.3 | CN25: 139.5 | CO25: 71.5 | CP25: -0.5
B26: Gold payable in concentrate | C26: koz | F26: 0 | G26: 0 | H26: 0 | I26: 0 | J26: 0 | K26: 0 | L26: 1.3 | M26: 6.5 | N26: 12.291872 | O26: 82.186729 | P26: 119.03955 | Q26: 189.7 | R26: 235.5 | S26: 153.6 | T26: 22.8 | U26: 70.5 | V26: 347.9 | W26: 176.4 | Y26: 0 | Z26: 0 | AA26: 0 | AB26: 0 | AC26: 0 | AD26: 0 | AE26: 0 | AF26: 0 | AG26: 0 | AH26: 0 | AI26: 0 | AJ26: 0 | AK26: 0 | AL26: 0 | AM26: 0 | AN26: 0 | AO26: 0 | AP26: 0 | AQ26: 0 | AR26: 0 | AS26: 0 | AT26: 0 | AU26: 0 | AV26: 0 | AW26: 0 | AX26: 1.3 | AY26: 0 | AZ26: 0 | BA26: 0 | BB26: 0 | BC26: 0 | BD26: 6.5 | BE26: 0 | BF26: 3.8113592 | BG26: 6.6916971 | BH26: 1.788816 | BI26: 6.0794973 | BJ26: 14.772068 | BK26: 25.563395 | BL26: 35.771767 | BM26: 19.726357 | BN26: 23.11319 | BO26: 56.5 | BP26: 19.7 | BQ26: 55.1 | BR26: 46.7 | BS26: 49.8 | BT26: 38.1 | BU26: 46.5 | BV26: 50.8 | BW26: 76.4 | BX26: 61.8 | BY26: 48.5 | BZ26: 32.4 | CA26: 55.5 | CB26: 17.2 | CC26: 17.4 | CD26: 0 | CE26: 5.4 | CF26: 0 | CH26: 17.4 | CI26: 5.4 | CJ26: 3.1 | CK26: 67.4 | CL26: 184.6 | CM26: 163.3 | CN26: 116.4 | CO26: 60 | CP26: -0.4
B27: Total gold produced2 | C27: koz | F27: 1214.3533 | G27: 1221.6179 | H27: 1230.935 | I27: 1277 | J27: 1381.3371 | K27: 1568.94 | L27: 1651.7 | M27: 1695.5 | N27: 1763.3539 | O27: 1967.846 | P27: 2160.1596 | Q27: 2440.1 | R27: 2841.2 | S27: 2766.1 | T27: 2717.4 | U27: 2541.3 | V27: 2902.2 | W27: 3001.6 | Y27: 211.23281 | Z27: 257.46116 | AA27: 408.16837 | AB27: 338.7278 | AC27: 172.2991 | AD27: 391.776 | AE27: 330.96931 | AF27: 326.57351 | AG27: 201.14591 | AH27: 276.84218 | AI27: 444.73877 | AJ27: 308.20811 | AK27: 189.7745 | AL27: 266.2255 | AM27: 419.49688 | AN27: 402.50312 | AO27: 231.79707 | AP27: 321.523 | AQ27: 463.86163 | AR27: 364.15539 | AS27: 302.5 | AT27: 367.1 | AU27: 449.5 | AV27: 449.84 | AW27: 319.9 | AX27: 400.5 | AY27: 466.8 | AZ27: 464.5 | BA27: 330.6 | BB27: 412.6 | BC27: 492.3 | BD27: 460 | BE27: 352.73074 | BF27: 431.1565 | BG27: 513.59719 | BH27: 465.86945 | BI27: 384.33132 | BJ27: 455.19366 | BK27: 554.95615 | BL27: 573.36488 | BM27: 450.20625 | BN27: 487.85332 | BO27: 642.3 | BP27: 579.8 | BQ27: 506.5 | BR27: 602 | BS27: 691.2 | BT27: 640.4 | BU27: 600.7 | BV27: 683.8 | BW27: 752.74944 | BX27: 804 | BY27: 594.9 | BZ27: 690.4 | CA27: 771.1 | CB27: 709.7 | CC27: 591.7 | CD27: 671.5 | CE27: 770 | CF27: 684.2 | CH27: 1263.2 | CI27: 1454.2 | CJ27: 1067.6 | CK27: 1473.7 | CL27: 1447.9 | CM27: 1454.3 | CN27: 1472.9 | CO27: 1528.7 | CP27: 1310.9
B30: OLIMPIADA
B32: Mining
B33: Total rock moved | C33: 000 m3 | F33: 32840.9 | G33: 30622.4 | H33: 24055.1 | I33: 22053.3 | J33: 16937.02 | K33: 24368.4 | L33: 25052.2 | M33: 24122.1 | N33: 22339.83 | O33: 19513.5 | P33: 28074.4 | Q33: 46745.6 | R33: 50014.323 | S33: 43889.8 | T33: 50245 | U33: 50538 | V33: 56123 | W33: 72779 | Y33: 7642.2 | Z33: 7693.7 | AA33: 9066.2 | AB33: 8438.8 | AC33: 8206.5 | AD33: 7508.3 | AE33: 7605.2 | AF33: 7302.4 | AG33: 6196 | AH33: 5531.5 | AI33: 6037.4 | AJ33: 6290.2 | AK33: 5856.6 | AL33: 5688 | AM33: 5002 | AN33: 5506.7 | AO33: 4153.62 | AP33: 4162.5 | AQ33: 4256 | AR33: 4364.9 | AS33: 5992.5 | AT33: 6136 | AU33: 6106 | AV33: 6133.9 | AW33: 6660.3 | AX33: 5788.1 | AY33: 6236 | AZ33: 6367.8 | BA33: 5162.7 | BB33: 5748 | BC33: 6602 | BD33: 6609.4 | BE33: 5844.61 | BF33: 5362.5 | BG33: 5554.32 | BH33: 5578.4 | BI33: 5429.9 | BJ33: 3772.7 | BK33: 4537.4 | BL33: 5773.5 | BM33: 5456.4 | BN33: 6030.7 | BO33: 7683.6 | BP33: 8903.7 | BQ33: 10530.7 | BR33: 10966.8 | BS33: 12261.5 | BT33: 12986.6 | BU33: 11896 | BV33: 12310.251 | BW33: 13110.572 | BX33: 12697.5 | BY33: 12418.8 | BZ33: 9232.9 | CA33: 11165.1 | CB33: 11073 | CC33: 10848.943 | CD33: 11368 | CE33: 13713 | CF33: 14315 | CH33: 22217 | CI33: 28028 | CJ33: 27765 | CK33: 22773 | CL33: 26847 | CM33: 29276 | CN33: 31949 | CO33: 40830 | CP33: 42493
B34: Stripping | C34: 000 m3 | F34: 30947.9 | G34: 30061.2 | H34: 20083.6 | I34: 18525.9 | J34: 14329.4 | K34: 21383.9 | L34: 20756.928 | M34: 21897.89 | N34: 21311.466 | O34: 15890.373 | P34: 23659.759 | Q34: 40165.974 | R34: 42509.436 | S34: 37993.843 | T34: 45973 | U34: 43539 | V34: 43143 | W34: 65774 | Y34: 6566.4 | Z34: 7400.4 | AA34: 8731.7 | AB34: 8249.4 | AC34: 8049.1 | AD34: 7347.2 | AE34: 7428 | AF34: 7236.9 | AG34: 5670.3 | AH34: 4623.2 | AI34: 4703.3 | AJ34: 5086.8 | AK34: 4787.1 | AL34: 4787.1 | AM34: 4293.2 | AN34: 4658.5 | AO34: 3380.8 | AP34: 3579.3 | AQ34: 3658.5 | AR34: 3710.8 | AS34: 4879.1 | AT34: 5255.5 | AU34: 5512 | AV34: 5737.3 | AW34: 5928.9 | AX34: 4530.6 | AY34: 5080.6 | AZ34: 5216.828 | BA34: 3982.4 | BB34: 4973.6 | BC34: 6373.49 | BD34: 6568.4 | BE34: 5584.3 | BF34: 5131.31 | BG34: 5371.151 | BH34: 5224.7048 | BI34: 4933.609 | BJ34: 3020.177 | BK34: 3733.5886 | BL34: 4202.9984 | BM34: 4378.9412 | BN34: 4934.4186 | BO34: 6583.9313 | BP34: 7762.468 | BQ34: 9291.7162 | BR34: 9626.8531 | BS34: 10129.434 | BT34: 11117.971 | BU34: 10023.949 | BV34: 10256.297 | BW34: 11283.222 | BX34: 10945.968 | BY34: 10920.32 | BZ34: 7702.0133 | CA34: 9660.5475 | CB34: 9711 | CC34: 9656.8407 | CD34: 10248.856 | CE34: 13060 | CF34: 13007 | CH34: 19906 | CI34: 26067 | CJ34: 25641 | CK34: 17898 | CL34: 20311 | CM34: 22832 | CN34: 26718 | CO34: 39056 | CP34: 41013
B35: Stripping ratio | C35: m3/t | F35: 6.9189787 | G35: 19.839757 | H35: 1.894161 | I35: 1.9467729 | J35: 2.0352729 | K35: 2.6543638 | L35: 1.7897972 | M35: 3.6463684 | N35: 7.6756308 | O35: 1.6243774 | P35: 1.9419336 | Q35: 2.2118111 | R35: 2.0522587 | S35: 2.3348008 | T35: 3.9 | U35: 2.3 | V35: 1.2 | W35: 3.5 | Y35: 2.7033347 | Z35: 10.657258 | AA35: 10.071165 | AB35: 17.097202 | AC35: 18.939059 | AD35: 16.893999 | AE35: 15.526756 | AF35: 40.909553 | AG35: 3.994857 | AH35: 1.9208908 | AI35: 1.3333239 | AJ35: 1.5655546 | AK35: 1.6577553 | AL35: 1.9743875 | AM35: 2.2433325 | AN35: 2.0341462 | AO35: 1.6202512 | AP35: 2.273091 | AQ35: 2.2677403 | AR35: 2.101222 | AS35: 1.6230394 | AT35: 2.2125719 | AU35: 3.4367089 | AV35: 5.3578066 | AW35: 3.0021571 | AX35: 1.3343783 | AY35: 1.6286115 | AZ35: 1.67873 | BA35: 1.2496509 | BB35: 2.3786886 | BC35: 10.330023 | BD35: 59.33514 | BE35: 7.9453361 | BF35: 8.2204867 | BG35: 10.862221 | BH35: 5.4710096 | BI35: 3.6818527 | BJ35: 1.4864451 | BK35: 1.7203162 | BL35: 0.99119022 | BM35: 1.4725137 | BN35: 1.6308155 | BO35: 2.1692737 | BP35: 2.4650581 | BQ35: 2.7171977 | BR35: 2.6030809 | BS35: 1.7213746 | BT35: 2.1557254 | BU35: 1.9400469 | BV35: 1.8092173 | BW35: 2.2371867 | BX35: 2.2642637 | BY35: 2.6404345 | BZ35: 1.822855 | CA35: 2.3264049 | CB35: 2.6 | CC35: 2.9350295 | CD35: 3.3150686 | CE35: 7.3 | CF35: 3.6 | CH35: 3.1 | CI35: 4.8 | CJ35: 4.4 | CK35: 1.3 | CL35: 1.1 | CM35: 1.3 | CN35: 1.9 | CO35: 8.5 | CP35: 10.5
B36: Ore mined | C36: kT | F36: 4472.9 | G36: 1515.2 | H36: 10602.9 | I36: 9516.21 | J36: 7040.53 | K36: 8056.13 | L36: 11597.363 | M36: 6005.397 | N36: 2776.51 | O36: 9782.4391 | P36: 12183.609 | Q36: 18159.767 | R36: 20713.489 | S36: 16272.841 | T36: 11791 | U36: 19316 | V36: 35827 | W36: 19032 | Y36: 2429 | Z36: 694.4 | AA36: 867 | AB36: 482.5 | AC36: 425 | AD36: 434.9 | AE36: 478.4 | AF36: 176.9 | AG36: 1419.4 | AH36: 2406.8 | AI36: 3527.5 | AJ36: 3249.2 | AK36: 2887.7 | AL36: 2424.6 | AM36: 1913.76 | AN36: 2290.15 | AO36: 2086.59 | AP36: 1574.64 | AQ36: 1613.28 | AR36: 1766.02 | AS36: 3006.15 | AT36: 2375.29 | AU36: 1603.86 | AV36: 1070.83 | AW36: 1974.88 | AX36: 3395.289 | AY36: 3119.59 | AZ36: 3107.604 | BA36: 3186.81 | BB36: 2090.9 | BC36: 616.987 | BD36: 110.7 | BE36: 702.84 | BF36: 624.21 | BG36: 494.48 | BH36: 954.98 | BI36: 1339.98 | BJ36: 2031.812 | BK36: 2170.2921 | BL36: 4240.355 | BM36: 2973.7863 | BN36: 3025.7368 | BO36: 3035.0856 | BP36: 3149 | BQ36: 3419.5952 | BR36: 3698.2534 | BS36: 5886 | BT36: 5157.4152 | BU36: 5166.8594 | BV36: 5668.9136 | BW36: 5043.487 | BX36: 4834.2285 | BY36: 4135.8042 | BZ36: 4225.2474 | CA36: 4152.5649 | CB36: 3759 | CC36: 3290.2023 | CD36: 3091.597 | CE36: 1799 | CF36: 3610 | CH36: 6382 | CI36: 5409 | CJ36: 5863 | CK36: 13453 | CL36: 18038 | CM36: 17789 | CN36: 14429 | CO36: 4603 | CP36: 3899
B37: Average grade in ore mined | C37: g/t | F37: 7.1399092 | G37: 2.6700766 | H37: 3.0319818 | I37: 3.1876136 | J37: 3.4272045 | K37: 3.3582465 | L37: 3.6283083 | M37: 3.6834434 | N37: 2.6740296 | O37: 3.3698158 | P37: 4.08 | Q37: 3.7060882 | R37: 3.4155962 | S37: 3.1820679 | T37: 2.8 | U37: 2.51 | V37: 2.93 | W37: 2.85 | Y37: 7.9872787 | Z37: 7.015409 | AA37: 5.8758939 | AB37: 5.3245596 | AC37: 3.444 | AD37: 2.7461485 | AE37: 2.1875 | AF37: 1.9287733 | AG37: 2.2996336 | AH37: 2.6582184 | AI37: 3.4488448 | AJ37: 3.1761972 | AK37: 3.1470374 | AL37: 2.9685309 | AM37: 3.2006626 | AN37: 3.459817 | AO37: 3.3455091 | AP37: 3.2471422 | AQ37: 3.361357 | AR37: 3.744431 | AS37: 3.2328327 | AT37: 3.3350665 | AU37: 3.4527453 | AV37: 3.6202012 | AW37: 3.5642875 | AX37: 3.6392189 | AY37: 3.5150773 | AZ37: 3.7707404 | BA37: 3.8760171 | BB37: 3.6311875 | BC37: 3.0326733 | BD37: 2.7537489 | BE37: 2.7138182 | BF37: 2.4452668 | BG37: 2.6876315 | BH37: 2.7872311 | BI37: 3.1784168 | BJ37: 3.4215357 | BK37: 3.3365482 | BL37: 3.422544 | BM37: 4.0717634 | BN37: 4.1758435 | BO37: 4.187951 | BP37: 3.9008394 | BQ37: 3.7920595 | BR37: 4.0384783 | BS37: 3.4803614 | BT37: 3.6682864 | BU37: 3.3568292 | BV37: 3.4802584 | BW37: 3.5174293 | BX37: 3.2963388 | BY37: 2.9343648 | BZ37: 3.5240057 | CA37: 3.2964542 | CB37: 2.94 | CC37: 3.079387 | CD37: 3.2425619 | CE37: 2.43 | CF37: 2.36 | CH37: 3.16 | CI37: 2.38 | CJ37: 2.04 | CK37: 2.72 | CL37: 2.89 | CM37: 2.97 | CN37: 3.12 | CO37: 1.99 | CP37: 1.42
B39: Processing
B40: Ore processed | C40: kT | F40: 6230.528 | G40: 6623.422 | H40: 8876.952 | I40: 7377.3 | J40: 8050.668 | K40: 8068.497 | L40: 7822.351 | M40: 8525.79 | N40: 9506.01 | O40: 11336.194 | P40: 12441.628 | Q40: 13266.535 | R40: 13908 | S40: 14048.351 | T40: 15061 | U40: 15189 | V40: 15373 | W40: 15325 | Y40: 1209.01 | Z40: 1262.75 | AA40: 1970.899 | AB40: 1787.869 | AC40: 1149.249 | AD40: 1774.962 | AE40: 1621.541 | AF40: 2077.67 | AG40: 2335.434 | AH40: 2036.055 | AI40: 2404.43 | AJ40: 2101.033 | AK40: 1639.16 | AL40: 1897.511 | AM40: 1758.434 | AN40: 2082.195 | AO40: 2021.225 | AP40: 2000.643 | AQ40: 2095.994 | AR40: 1932.806 | AS40: 2081.82 | AT40: 1870.173 | AU40: 1860.479 | AV40: 2256.025 | AW40: 1845.293 | AX40: 1951.108 | AY40: 2145.281 | AZ40: 1880.669 | BA40: 1984.782 | BB40: 2214.56 | BC40: 2186.548 | BD40: 2139.9 | BE40: 2262.603 | BF40: 2499.326 | BG40: 2311.621 | BH40: 2432.46 | BI40: 2509.381 | BJ40: 2693.387 | BK40: 2777.724 | BL40: 3355.702 | BM40: 2929.779 | BN40: 2882.211 | BO40: 3489.698 | BP40: 3139.94 | BQ40: 3155.13 | BR40: 3336.777 | BS40: 3364.912 | BT40: 3409.716 | BU40: 3489 | BV40: 3358 | BW40: 3415.588 | BX40: 3644.589 | BY40: 3503 | BZ40: 3539 | CA40: 3757.355 | CB40: 3249 | CC40: 3668.21 | CD40: 3648 | CE40: 4009 | CF40: 3736 | CH40: 7316 | CI40: 7745 | CJ40: 7613 | CK40: 7576 | CL40: 7538 | CM40: 7835 | CN40: 7541 | CO40: 7784 | CP40: 7550
B41: Average grade in ore processed | C41: g/t | F41: 5.1225277 | G41: 5.0882475 | H41: 3.9789006 | I41: 3.7705574 | J41: 3.4336553 | K41: 3.4258005 | L41: 3.6011636 | M41: 3.631911 | N41: 3.1822684 | O41: 3.313392 | P41: 3.8 | Q41: 4.1 | R41: 3.92 | S41: 3.3969533 | T41: 3 | U41: 2.77 | V41: 3.96 | W41: 3.59 | Y41: 5.061397 | Z41: 5.3521502 | AA41: 4.8911542 | AB41: 5.2567466 | AC41: 5.1255464 | AD41: 6.4737636 | AE41: 4.7217827 | AF41: 4.1699753 | AG41: 3.7074499 | AH41: 3.9241257 | AI41: 4.5924834 | AJ41: 3.6315301 | AK41: 3.5958465 | AL41: 3.7524872 | AM41: 3.865031 | AN41: 3.8447781 | AO41: 3.4879754 | AP41: 3.2714947 | AQ41: 3.288098 | AR41: 3.7025492 | AS41: 3.3843947 | AT41: 3.5637395 | AU41: 3.392813 | AV41: 3.3768658 | AW41: 3.5653492 | AX41: 3.5128959 | AY41: 3.6116485 | AZ41: 3.7159177 | BA41: 3.7484546 | BB41: 3.5789236 | BC41: 3.5924598 | BD41: 3.6189627 | BE41: 3.3626981 | BF41: 3.3370561 | BG41: 3.0758835 | BH41: 2.9564954 | BI41: 2.9946286 | BJ41: 2.9258163 | BK41: 3.4317607 | BL41: 3.7648608 | BM41: 3.4526673 | BN41: 3.8426273 | BO41: 3.9324365 | BP41: 3.9401707 | BQ41: 4.1659437 | BR41: 4.0956082 | BS41: 4.12 | BT41: 4.0067258 | BU41: 3.7617098 | BV41: 4.03 | BW41: 4.0149299 | BX41: 3.88 | BY41: 3.2004678 | BZ41: 3.4747018 | CA41: 3.5596269 | CB41: 3.34 | CC41: 3.0200148 | CD41: 3.0340849 | CE41: 3.03 | CF41: 2.93 | CH41: 3.03 | CI41: 2.98 | CJ41: 2.37 | CK41: 3.18 | CL41: 4.09 | CM41: 3.83 | CN41: 3.51 | CO41: 3.66 | CP41: 2.39
B42: Recovery | C42: % | F42: 0.84935448 | G42: 0.82183299 | H42: 0.74265872 | I42: 0.6642177 | J42: 0.69117844 | K42: 0.73681682 | L42: 0.7360542 | M42: 0.76879659 | N42: 0.80054654 | O42: 0.8096997 | P42: 0.807 | Q42: 0.793 | R42: 0.824 | S42: 0.84549529 | T42: 0.84 | U42: 0.821 | V42: 0.834 | W42: 0.849 | Y42: 0.89916766 | Z42: 0.89140511 | AA42: 0.8255764 | AB42: 0.80789116 | AC42: 0.75947884 | AD42: 0.85430536 | AE42: 0.82541028 | AF42: 0.82821561 | AG42: 0.7802756 | AH42: 0.72655093 | AI42: 0.76667677 | AJ42: 0.67924673 | AK42: 0.63628021 | AL42: 0.6370256 | AM42: 0.70118668 | AN42: 0.67546715 | AO42: 0.69891979 | AP42: 0.72397048 | AQ42: 0.62523826 | AR42: 0.70637786 | AS42: 0.73728431 | AT42: 0.77701805 | AU42: 0.68258767 | AV42: 0.74324808 | AW42: 0.7406716 | AX42: 0.73752993 | AY42: 0.73084952 | AZ42: 0.73603027 | BA42: 0.76072564 | BB42: 0.77170912 | BC42: 0.77117025 | BD42: 0.77116188 | BE42: 0.7893373 | BF42: 0.80038561 | BG42: 0.81823248 | BH42: 0.79510616 | BI42: 0.80249632 | BJ42: 0.81341229 | BK42: 0.81735808 | BL42: 0.80589014 | BM42: 0.79886207 | BN42: 0.81278374 | BO42: 0.81411429 | BP42: 0.8018649 | BQ42: 0.8 | BR42: 0.79 | BS42: 0.792 | BT42: 0.788 | BU42: 0.80777126 | BV42: 0.821 | BW42: 0.82482018 | BX42: 0.839 | BY42: 0.84777183 | BZ42: 0.8542286 | CA42: 0.86123255 | CB42: 0.84942428 | CC42: 0.824952 | CD42: 0.838 | CE42: 0.84581531 | CF42: 0.851 | CH42: 0.831 | CI42: 0.848 | CJ42: 0.812 | CK42: 0.828 | CL42: 0.829 | CM42: 0.839 | CN42: 0.845 | CO42: 0.853 | CP42: 0.839
B43: Total Dore gold output | C43: koz | F43: 853.92514 | G43: 879.34667 | H43: 825.34529 | I43: 581.71875 | J43: 573.23382 | K43: 658.76234 | L43: 697.73671 | M43: 726.16101 | N43: 758.39551 | O43: 956.27064 | P43: 1176.6 | Q43: 1325.2828 | R43: 1385.8 | S43: 1229.3241 | T43: 1112.8 | U43: 1052.2 | V43: 1501.7 | W43: 1441.3 | Y43: 185.5236 | Z43: 187.53298 | AA43: 246.66324 | AB43: 234.20531 | AC43: 167.11138 | AD43: 293.18826 | AE43: 193.76803 | AF43: 225.279 | AG43: 214.61015 | AH43: 179.87046 | AI43: 271.61041 | AJ43: 159.25428 | AK43: 110.52198 | AL43: 149.99335 | AM43: 163.73957 | AN43: 157.46386 | AO43: 144.24969 | AP43: 148.87671 | AQ43: 113.15231 | AR43: 166.95511 | AS43: 175.37655 | AT43: 162.49734 | AU43: 128.20851 | AV43: 192.67995 | AW43: 161.49949 | AX43: 159.48056 | AY43: 180.56924 | AZ43: 196.18742 | BA43: 176.28378 | BB43: 185.32639 | BC43: 178.80425 | BD43: 185.74659 | BE43: 181.83549 | BF43: 204.22542 | BG43: 185.788 | BH43: 186.5466 | BI43: 179.46503 | BJ43: 206.14804 | BK43: 256.77488 | BL43: 313.88269 | BM43: 243.8 | BN43: 278.31095 | BO43: 347.44338 | BP43: 307.0512 | BQ43: 318.03988 | BR43: 340.58238 | BS43: 346.7 | BT43: 319.94285 | BU43: 348.20238 | BV43: 343.1 | BW43: 356.1 | BX43: 338.4 | BY43: 323.72728 | BZ43: 305 | CA43: 319.2 | CB43: 281.4 | CC43: 271.8155 | CD43: 279.5 | CE43: 293 | CF43: 268.5 | CH43: 551.3 | CI43: 561.5 | CJ43: 473.7 | CK43: 578.5 | CL43: 788.9 | CM43: 712.8 | CN43: 739.9 | CO43: 701.4 | CP43: 489.1
B44: Total refined gold output | C44: koz | F44: 861.07111 | G44: 872.81467 | H44: 839.19852 | I44: 585 | J44: 566 | K44: 653 | L44: 691.3 | M44: 725.5 | N44: 741.12293 | O44: 816.94752 | P44: 1007.3 | Q44: 1065.4 | R44: 1071.7 | S44: 1001.8 | T44: 1082.8 | U44: 959.7 | V44: 1075.6 | W44: 1265.7 | Y44: 175.19237 | Z44: 172.21109 | AA44: 258.92755 | AB44: 254.74011 | AC44: 137.99542 | AD44: 312.19704 | AE44: 192.46999 | AF44: 230.15223 | AG44: 193.61692 | AH44: 149.86808 | AI44: 283.88199 | AJ44: 211.83152 | AK44: 111 | AL44: 122 | AM44: 156 | AN44: 196 | AO44: 110.2 | AP44: 137.7 | AQ44: 158.4 | AR44: 159.7 | AS44: 156.6 | AT44: 161.8 | AU44: 133.2 | AV44: 201.4 | AW44: 156.6 | AX44: 151.6 | AY44: 185.8 | AZ44: 197.3 | BA44: 167 | BB44: 187.3 | BC44: 189.2 | BD44: 182 | BE44: 161.59117 | BF44: 194.91414 | BG44: 188.49139 | BH44: 196.12622 | BI44: 150.86987 | BJ44: 179.88041 | BK44: 213.93636 | BL44: 272.26088 | BM44: 219.10426 | BN44: 226.19027 | BO44: 264.09889 | BP44: 297.9 | BQ44: 213.1 | BR44: 276 | BS44: 283 | BT44: 293.3 | BU44: 248.3 | BV44: 282.7 | BW44: 239.9 | BX44: 300.8 | BY44: 215 | BZ44: 264 | CA44: 254.8 | CB44: 268 | CC44: 242.4 | CD44: 269.9 | CE44: 281.6 | CF44: 289 | CH44: 512.3 | CI44: 570.6 | CJ44: 427.7 | CK44: 532 | CL44: 568.1 | CM44: 507.5 | CN44: 600.1 | CO44: 665.6 | CP44: 495.7
B45: Gold contained in concentrate | C45: koz | F45: 0 | G45: 0 | H45: 0 | I45: 0 | J45: 0 | K45: 0 | L45: 2 | M45: 10 | N45: 18.910573 | O45: 126.44112 | P45: 170 | Q45: 256.3 | R45: 317.5 | S45: 198.01792 | T45: 29.8 | U45: 83.7 | V45: 419.5 | W45: 211 | Y45: 0 | Z45: 0 | AA45: 0 | AB45: 0 | AC45: 0 | AD45: 0 | AE45: 0 | AF45: 0 | AG45: 0 | AH45: 0 | AI45: 0 | AJ45: 0 | AK45: 0 | AL45: 0 | AM45: 0 | AN45: 0 | AO45: 0 | AP45: 0 | AQ45: 0 | AR45: 0 | AS45: 0 | AT45: 0 | AU45: 0 | AV45: 0 | AW45: 0 | AX45: 2 | AY45: 0 | AZ45: 0 | BA45: 0 | BB45: 0 | BC45: 0 | BD45: 10 | BE45: 0 | BF45: 5.8636295 | BG45: 10.294919 | BH45: 2.7520247 | BI45: 9.3530728 | BJ45: 22.726259 | BK45: 39.328301 | BL45: 55.033488 | BM45: 28.18051 | BN45: 33.018844 | BO45: 80.7 | BP45: 28.14752 | BQ45: 74.4 | BR45: 63.1 | BS45: 67.4 | BT45: 51.4 | BU45: 62.7 | BV45: 68.5 | BW45: 103 | BX45: 83.3 | BY45: 61.9 | BZ45: 44.1 | CA45: 70 | CB45: 22 | CC45: 22.714148 | CD45: 0.1 | CE45: 7 | CF45: 0 | CH45: 22.8 | CI45: 7 | CJ45: 4 | CK45: 79.7 | CL45: 221.2 | CM45: 198.3 | CN45: 139.5 | CO45: 71.5 | CP45: -0.5
B46: Gold payable in concentrate | C46: koz | F46: 0 | G46: 0 | H46: 0 | I46: 0 | J46: 0 | K46: 0 | L46: 1.52 | M46: 7.6 | N46: 14.372035 | O46: 96.095252 | P46: 119 | Q46: 189.7 | R46: 235.5 | S46: 153.6 | T46: 22.8 | U46: 70.5 | V46: 347.9 | W46: 176.4 | Y46: 0 | Z46: 0 | AA46: 0 | AB46: 0 | AC46: 0 | AD46: 0 | AE46: 0 | AF46: 0 | AG46: 0 | AH46: 0 | AI46: 0 | AJ46: 0 | AK46: 0 | AL46: 0 | AM46: 0 | AN46: 0 | AO46: 0 | AP46: 0 | AQ46: 0 | AR46: 0 | AS46: 0 | AT46: 0 | AU46: 0 | AV46: 0 | AW46: 0 | AX46: 1.52 | AY46: 0 | AZ46: 0 | BA46: 0 | BB46: 0 | BC46: 0 | BD46: 7.6 | BE46: 0 | BF46: 4.4563584 | BG46: 7.8241381 | BH46: 2.0915388 | BI46: 7.1083353 | BJ46: 17.271957 | BK46: 29.889509 | BL46: 41.825451 | BM46: 19.726357 | BN46: 23.11319 | BO46: 56.5 | BP46: 19.7 | BQ46: 55.1 | BR46: 46.7 | BS46: 49.8 | BT46: 38.1 | BU46: 46.5 | BV46: 50.8 | BW46: 76.4 | BX46: 61.8 | BY46: 48.5 | BZ46: 32.4 | CA46: 55.5 | CB46: 17.2 | CC46: 17.4 | CD46: 0 | CE46: 5.4 | CF46: 0 | CH46: 17.4 | CI46: 5.4 | CJ46: 3.1 | CK46: 64.7 | CL46: 184.6 | CM46: 163.3 | CN46: 116.4 | CO46: 60 | CP46: -0.4
B47: Total gold produced | C47: koz | F47: 861.07111 | G47: 872.81467 | H47: 839.19852 | I47: 585 | J47: 566 | K47: 653 | L47: 693.3 | M47: 735.5 | N47: 760.03351 | O47: 943.38864 | P47: 1177.3 | Q47: 1321.7 | R47: 1389.2 | S47: 1199.8 | T47: 1112.7 | U47: 1043.4 | V47: 1495.1 | W47: 1476.7 | Y47: 175.19237 | Z47: 172.21109 | AA47: 258.92755 | AB47: 254.74011 | AC47: 137.99542 | AD47: 312.19704 | AE47: 192.46999 | AF47: 230.15223 | AG47: 193.61692 | AH47: 149.86808 | AI47: 283.88199 | AJ47: 211.83152 | AK47: 111 | AL47: 122 | AM47: 156 | AN47: 196 | AO47: 110.2 | AP47: 137.7 | AQ47: 158.4 | AR47: 159.7 | AS47: 156.6 | AT47: 161.8 | AU47: 133.2 | AV47: 201.4 | AW47: 156.6 | AX47: 153.6 | AY47: 185.8 | AZ47: 197.3 | BA47: 167 | BB47: 187.3 | BC47: 189.2 | BD47: 192 | BE47: 161.59117 | BF47: 200.77777 | BG47: 198.78631 | BH47: 198.87825 | BI47: 160.22294 | BJ47: 202.60667 | BK47: 253.26466 | BL47: 327.29437 | BM47: 247.28477 | BN47: 259.20912 | BO47: 344.79889 | BP47: 326 | BQ47: 287.5 | BR47: 339.1 | BS47: 350.4 | BT47: 344.7 | BU47: 311 | BV47: 351.2 | BW47: 342.9 | BX47: 384.1 | BY47: 276.93543 | BZ47: 308.1 | CA47: 324.8 | CB47: 290 | CC47: 265.13838 | CD47: 270 | CE47: 288.6 | CF47: 289 | CH47: 535.1 | CI47: 577.6 | CJ47: 431.7 | CK47: 611.7 | CL47: 789.3 | CM47: 705.8 | CN47: 739.6 | CO47: 737.1 | CP47: 495.2
B50: BLAGODATNOYE
B52: Mining
B53: Total rock moved | C53: 000 m3 | F53: 0 | G53: 1660.1 | H53: 7740 | I53: 11148.009 | J53: 13522.399 | K53: 15355.086 | L53: 13320.971 | M53: 14695.74 | N53: 16432.641 | O53: 17635.607 | P53: 27276.641 | Q53: 28058.289 | R53: 24433.258 | S53: 23519 | T53: 28119 | U53: 28538 | V53: 23333 | W53: 35363 | Y53: 0 | Z53: 0 | AA53: 0 | AB53: 0 | AC53: 0 | AD53: 51.7 | AE53: 735.6 | AF53: 872.8 | AG53: 1545.3 | AH53: 611.1 | AI53: 1206.8 | AJ53: 4376.8 | AK53: 2348.7 | AL53: 2683 | AM53: 3520.209 | AN53: 2596.1 | AO53: 3211.3 | AP53: 3296.899 | AQ53: 3460.8 | AR53: 3553.4 | AS53: 3815.2238 | AT53: 3851.8 | AU53: 3850.447 | AV53: 3837.615 | AW53: 3271.94 | AX53: 3287.2486 | AY53: 3365.7624 | AZ53: 3396.0204 | BA53: 3492.924 | BB53: 3720.7108 | BC53: 3822.6752 | BD53: 3659.43 | BE53: 3581.3588 | BF53: 4323.5638 | BG53: 4304.0468 | BH53: 4223.672 | BI53: 3853.4752 | BJ53: 4324.4689 | BK53: 5125.0464 | BL53: 4332.6166 | BM53: 6180.2232 | BN53: 6391.6672 | BO53: 7371.4285 | BP53: 7333.322 | BQ53: 6931.9 | BR53: 7110.2661 | BS53: 7478.3228 | BT53: 6537.8 | BU53: 6139.684 | BV53: 5887.0776 | BW53: 6382.1232 | BX53: 6024.3731 | BY53: 5986.5 | BZ53: 5704.3 | CA53: 5914.2 | CB53: 5914 | CC53: 6085.3 | CD53: 7179.9 | CE53: 7550.1 | CF53: 7304 | CH53: 13265 | CI53: 14854 | CJ53: 14187 | CK53: 14351 | CL53: 11646 | CM53: 11687 | CN53: 16340 | CO53: 19023 | CP53: 20554
...

Sheet Check to FY2024 Data
B2: PJSC POLYUS | X2: QUARTERLY | CG2: SEMI-ANNUAL
B4: OPERATING RESULTS* | F4: 2007 | G4: 2008 | H4: 2009 | I4: 2010 | J4: 2011 | K4: 2012 | L4: 2013 | M4: 2014 | N4: 2015 | O4: 2016 | P4: 2017 | Q4: 2018 | R4: 2019 | S4: 2020 | T4: 2021 | U4: 2022 | V4: 2023 | W4: 2024 | X4: DATA | Y4: 1Q'07 | Z4: 2Q'07 | AA4: 3Q'07 | AB4: 4Q'07 | AC4: 1Q'08 | AD4: 2Q'08 | AE4: 3Q'08 | AF4: 4Q'08 | AG4: 1Q'09 | AH4: 2Q'09 | AI4: 3Q'09 | AJ4: 4Q'09 | AK4: 1Q'10 | AL4: 2Q'10 | AM4: 3Q'10 | AN4: 4Q'10 | AO4: 1Q'11 | AP4: 2Q'11 | AQ4: 3Q'11 | AR4: 4Q'11 | AS4: 1Q'12 | AT4: 2Q'12 | AU4: 3Q'12 | AV4: 4Q'12 | AW4: 1Q'13 | AX4: 2Q'13 | AY4: 3Q'13 | AZ4: 4Q'13 | BA4: 1Q'14 | BB4: 2Q'14 | BC4: 3Q'14 | BD4: 4Q'14 | BE4: 1Q'15 | BF4: 2Q'15 | BG4: 3Q'15 | BH4: 4Q'15 | BI4: 1Q'16 | BJ4: 2Q'16 | BK4: 3Q'16 | BL4: 4Q'16 | BM4: 1Q'17 | BN4: 2Q'17 | BO4: 3Q'17 | BP4: 4Q'17 | BQ4: 1Q'18 | BR4: 2Q'18 | BS4: 3Q'18 | BT4: 4Q'18 | BU4: 1Q'19 | BV4: 2Q'19 | BW4: 3Q'19 | BX4: 4Q'19 | BY4: 1Q'20 | BZ4: 2Q'20 | CA4: 3Q'20 | CB4: 4Q'20 | CC4: 1Q'21 | CD4: 2Q'21 | CE4: 3Q'21 | CF4: 4Q'21 | CG4: DATA | CH4: 1H'21 | CI4: 2H'21 | CJ4: 1H'22 | CK4: 2H'22 | CL4: 1H'23 | CM4: 2H'23 | CN4: 1H'24 | CO4: 2H'24
Y5: 39172 | Z5: 39263 | AA5: 39355 | AB5: 39447 | AC5: 39538 | AD5: 39629 | AE5: 39721 | AF5: 39813 | AG5: 39903 | AH5: 39994 | AI5: 40086 | AJ5: 40178 | AK5: 40268 | AL5: 40359 | AM5: 40451 | AN5: 40543 | AO5: 40633 | AP5: 40724 | AQ5: 40816 | AR5: 40908 | AS5: 40999 | AT5: 41090 | AU5: 41182 | AV5: 41274 | AW5: 41364 | AX5: 41455 | AY5: 41547 | AZ5: 41639 | BA5: 41729 | BB5: 41820 | BC5: 41912 | BD5: 42004 | BE5: 42094 | BF5: 42185 | BG5: 42277 | BH5: 42369 | BI5: 42460 | BJ5: 42551 | BK5: 42643 | BL5: 42735 | BM5: 42825 | BN5: 42916
G6: 2008 | H6: 2009 | I6: 2010 | J6: 2011 | K6: 2012 | L6: 2013 | M6: 2014 | N6: 2015 | O6: 2016 | Y6: 2007 | Z6: 2007 | AA6: 2007 | AB6: 2007 | AC6: 2008 | AD6: 2008 | AE6: 2008 | AF6: 2008 | AG6: 2009 | AH6: 2009 | AI6: 2009 | AJ6: 2009 | AK6: 2010 | AL6: 2010 | AM6: 2010 | AN6: 2010 | AO6: 2011 | AP6: 2011 | AQ6: 2011 | AR6: 2011 | AS6: 2012 | AT6: 2012 | AU6: 2012 | AV6: 2012 | AW6: 2013 | AX6: 2013 | AY6: 2013 | AZ6: 2013 | BA6: 2014 | BB6: 2014 | BC6: 2014 | BD6: 2014 | BE6: 2015 | BF6: 2015 | BG6: 2015 | BH6: 2015 | BI6: 2016 | BJ6: 2016 | BK6: 2016 | BL6: 2016 | BM6: 2017 | BN6: 2017
G7: 4 | H7: 4 | I7: 4 | J7: 4 | K7: 4 | L7: 4 | M7: 4 | N7: 4 | O7: 4 | Y7: 1 | Z7: 2 | AA7: 3 | AB7: 4 | AC7: 1 | AD7: 2 | AE7: 3 | AF7: 4 | AG7: 1 | AH7: 2 | AI7: 3 | AJ7: 4 | AK7: 1 | AL7: 2 | AM7: 3 | AN7: 4 | AO7: 1 | AP7: 2 | AQ7: 3 | AR7: 4 | AS7: 1 | AT7: 2 | AU7: 3 | AV7: 4 | AW7: 1 | AX7: 2 | AY7: 3 | AZ7: 4 | BA7: 1 | BB7: 2 | BC7: 3 | BD7: 4 | BE7: 1 | BF7: 2 | BG7: 3 | BH7: 4 | BI7: 1 | BJ7: 2 | BK7: 3 | BL7: 4 | BM7: 1 | BN7: 2
B10: CONSOLIDATED OPERATING RESULTS
B12: Mining
B13: Total rock moved | C13: 000 m3 | F13: 49474 | G13: 50759.2 | H13: 48477.1 | I13: 55609.719 | J13: 53466.339 | K13: 66703.426 | L13: 66351.174 | M13: 71238.621 | N13: 64505.2 | O13: 58073.24 | P13: 88417.645 | Q13: 116987.17 | R13: =Sheet1!R13-[1]Sheet1!R13 -> #ERROR! | S13: =Sheet1!S13-[1]Sheet1!S13 -> #ERROR! | T13: =Sheet1!T13-[1]Sheet1!T13 -> #ERROR! | U13: =Sheet1!U13-[1]Sheet1!U13 -> #ERROR! | V13: =Sheet1!V13-[1]Sheet1!V13 -> #ERROR! | W13: =Sheet1!W13-[1]Sheet1!W13 -> #ERROR! | Y13: 11240.8 | Z13: 11979.8 | AA13: 13172.6 | AB13: 13080.8 | AC13: 12297.8 | AD13: 12126.3 | AE13: 13092.3 | AF13: 13242.8 | AG13: 12336.1 | AH13: 10996.8 | AI13: 11060.4 | AJ13: 14083.8 | AK13: 12672.7 | AL13: 14100.84 | AM13: 14789.399 | AN13: 14046.78 | AO13: 12839.44 | AP13: 13033.499 | AQ13: 13535.6 | AR13: 14057.8 | AS13: 16052.224 | AT13: 16420 | AU13: 16955.787 | AV13: 17275.415 | AW13: 16764.84 | AX13: 15985.079 | AY13: 16653.765 | AZ13: 16947.49 | BA13: 16828.727 | BB13: 17943.646 | BC13: 19077.702 | BD13: 17388.546 | BE13: 16111.269 | BF13: 15897.364 | BG13: 16447.244 | BH13: 16049.324 | BI13: 15147.421 | BJ13: 13286.463 | BK13: 14608.546 | BL13: 15030.809 | BM13: 18577.86 | BN13: 20675.019 | BO13: 24435.882 | BP13: 24728.884 | BQ13: 26133.841 | BR13: 28319.993 | BS13: 31239.5 | BT13: 31293.839 | BU13: 30210.605 | BV13: 31582.96 | BW13: 33738.058 | BX13: 32420.617 | BY13: 32372.793 | BZ13: 28909.286 | CA13: 32210.497 | CB13: 30741 | CC13: 31587.145 | CD13: 33120.136 | CE13: 35728.513 | CF13: 35994.131 | CH13: =Sheet1!CH13-[1]Sheet1!CH13 -> #ERROR! | CI13: =Sheet1!CI13-[1]Sheet1!CI13 -> #ERROR! | CJ13: =Sheet1!CJ13-[1]Sheet1!CJ13 -> #ERROR! | CK13: =Sheet1!CK13-[1]Sheet1!CK13 -> #ERROR! | CL13: =Sheet1!CL13-[1]Sheet1!CL13 -> #ERROR! | CM13: =Sheet1!CM13-[1]Sheet1!CM13 -> #ERROR! | CN13: =Sheet1!CN13-[1]Sheet1!CN13 -> #ERROR! | CO13: =Sheet1!CO13-[1]Sheet1!CO13 -> #ERROR!
B14: Stripping | C14: 000 m3 | F14: 44255.4 | G14: 47543.4 | H14: 40990.8 | I14: 46878.11 | J14: 45316.98 | K14: 57255.939 | L14: 54551.748 | M14: 59447.684 | N14: 55628.078 | O14: 46326.125 | P14: 73419.891 | Q14: 99480.959 | R14: =Sheet1!R14-[1]Sheet1!R14 -> #ERROR! | S14: =Sheet1!S14-[1]Sheet1!S14 -> #ERROR! | T14: =Sheet1!T14-[1]Sheet1!T14 -> #ERROR! | U14: =Sheet1!U14-[1]Sheet1!U14 -> #ERROR! | V14: =Sheet1!V14-[1]Sheet1!V14 -> #ERROR! | W14: =Sheet1!W14-[1]Sheet1!W14 -> #ERROR! | Y14: 9493.2 | Z14: 10798.2 | AA14: 11986.7 | AB14: 11977.3 | AC14: 11517.8 | AD14: 11304.9 | AE14: 12215.2 | AF14: 12505.5 | AG14: 11029.6 | AH14: 9176.5 | AI14: 8844 | AJ14: 11940.7 | AK14: 10508.5 | AL14: 11879.9 | AM14: 12714.07 | AN14: 11775.64 | AO14: 10633.84 | AP14: 10970.28 | AQ14: 11678.23 | AR14: 12034.63 | AS14: 13352.909 | AT14: 13959.84 | AU14: 14725.86 | AV14: 15217.33 | AW14: 14186.86 | AX14: 12906.747 | AY14: 13532.922 | AZ14: 13925.22 | BA14: 12986.471 | BB14: 14632.106 | BC14: 16547.34 | BD14: 15281.767 | BE14: 14084.787 | BF14: 13594.275 | BG14: 14237.598 | BH14: 13711.418 | BI14: 12435.395 | BJ14: 10534.153 | BK14: 11892.836 | BL14: 11463.741 | BM14: 15169.448 | BN14: 17003.116 | BO14: 20478.305 | BP14: 20769.021 | BQ14: 22583.242 | BR14: 24443.357 | BS14: 25988.519 | BT14: 26465.841 | BU14: 24663.929 | BV14: 25231.141 | BW14: 26703.959 | BX14: 24964.445 | BY14: 25251.044 | BZ14: 21972.517 | CA14: 24879.049 | CB14: 24040.997 | CC14: 25065.507 | CD14: 26351.385 | CE14: 28957.238 | CF14: 29337.378 | CH14: =Sheet1!CH14-[1]Sheet1!CH14 -> #ERROR! | CI14: =Sheet1!CI14-[1]Sheet1!CI14 -> #ERROR! | CJ14: =Sheet1!CJ14-[1]Sheet1!CJ14 -> #ERROR! | CK14: =Sheet1!CK14-[1]Sheet1!CK14 -> #ERROR! | CL14: =Sheet1!CL14-[1]Sheet1!CL14 -> #ERROR! | CM14: =Sheet1!CM14-[1]Sheet1!CM14 -> #ERROR! | CN14: =Sheet1!CN14-[1]Sheet1!CN14 -> #ERROR! | CO14: =Sheet1!CO14-[1]Sheet1!CO14 -> #ERROR!
B15: Stripping ratio | C15: m3/t | F15: 4.7195188 | G15: 7.2307154 | H15: 2.282275 | I15: 2.171984 | J15: 2.2427523 | K15: 2.432232 | L15: 1.5976795 | M15: 1.9895471 | N15: 2.5271153 | O15: 1.5607303 | P15: 1.9418115 | Q15: 2.3221062 | R15: =Sheet1!R15-[1]Sheet1!R15 -> #ERROR! | S15: =Sheet1!S15-[1]Sheet1!S15 -> #ERROR! | T15: =Sheet1!T15-[1]Sheet1!T15 -> #ERROR! | U15: =Sheet1!U15-[1]Sheet1!U15 -> #ERROR! | V15: =Sheet1!V15-[1]Sheet1!V15 -> #ERROR! | W15: =Sheet1!W15-[1]Sheet1!W15 -> #ERROR! | Y15: 2.5836055 | Z15: 5.4202389 | AA15: 5.7509476 | AB15: 7.3652072 | AC15: 7.3305754 | AD15: 6.5937008 | AE15: 6.6405001 | AF15: 8.6244828 | AG15: 3.7230717 | AH15: 2.1362557 | AI15: 1.6338143 | AJ15: 2.2575199 | AK15: 1.9695805 | AL15: 2.1765992 | AM15: 2.4628131 | AN15: 2.0926082 | AO15: 1.9238029 | AP15: 2.1446257 | AQ15: 2.5501956 | AR15: 2.4147165 | AS15: 1.9730146 | AT15: 2.2648006 | AU15: 2.6415432 | AV15: 3.0228043 | AW15: 2.0137 | AX15: 1.4776626 | AY15: 1.5048463 | AZ15: 1.485875 | BA15: 1.3169155 | BB15: 1.7298207 | BC15: 2.6079088 | BD15: 2.9303889 | BE15: 2.807955 | BF15: 2.3544559 | BG15: 2.6189812 | BH15: 2.369639 | BI15: 1.8201588 | BJ15: 1.5161949 | BK15: 1.7443807 | BL15: 1.2618672 | BM15: 1.759813 | BN15: 1.8461579 | BO15: 2.0654897 | BP15: 2.0634894 | BQ15: 2.5601571 | BR15: 2.6234167 | BS15: 2.0508307 | BT15: 2.1999454 | BU15: 1.7712052 | BV15: 1.6110861 | BW15: 1.5279369 | BX15: 1.3131579 | BY15: 1.3854201 | BZ15: 1.2653916 | CA15: 1.3622617 | CB15: 1.3895227 | CC15: 1.5064184 | CD15: 1.5476812 | CE15: 1.7208735 | CF15: 1.7433396 | CH15: =Sheet1!CH15-[1]Sheet1!CH15 -> #ERROR! | CI15: =Sheet1!CI15-[1]Sheet1!CI15 -> #ERROR! | CJ15: =Sheet1!CJ15-[1]Sheet1!CJ15 -> #ERROR! | CK15: =Sheet1!CK15-[1]Sheet1!CK15 -> #ERROR! | CL15: =Sheet1!CL15-[1]Sheet1!CL15 -> #ERROR! | CM15: =Sheet1!CM15-[1]Sheet1!CM15 -> #ERROR! | CN15: =Sheet1!CN15-[1]Sheet1!CN15 -> #ERROR! | CO15: =Sheet1!CO15-[1]Sheet1!CO15 -> #ERROR!
B16: Ore mined | C16: kT | F16: 9377.1 | G16: 6575.2 | H16: 17960.5 | I16: 21583.083 | J16: 20205.968 | K16: 23540.492 | L16: 34144.363 | M16: 29880.009 | N16: 22012.481 | O16: 29682.338 | P16: 37810 | Q16: 42840.83 | R16: =Sheet1!R16-[1]Sheet1!R16 -> #ERROR! | S16: =Sheet1!S16-[1]Sheet1!S16 -> #ERROR! | T16: =Sheet1!T16-[1]Sheet1!T16 -> #ERROR! | U16: =Sheet1!U16-[1]Sheet1!U16 -> #ERROR! | V16: =Sheet1!V16-[1]Sheet1!V16 -> #ERROR! | W16: =Sheet1!W16-[1]Sheet1!W16 -> #ERROR! | Y16: 3674.4 | Z16: 1992.2 | AA16: 2084.3 | AB16: 1626.2 | AC16: 1571.2 | AD16: 1714.5 | AE16: 1839.5 | AF16: 1450 | AG16: 2962.5 | AH16: 4295.6 | AI16: 5413.1 | AJ16: 5289.3 | AK16: 5335.4 | AL16: 5458.01 | AM16: 5162.4178 | AN16: 5627.255 | AO16: 5527.51 | AP16: 5115.2423 | AQ16: 4579.3468 | AR16: 4983.8687 | AS16: 6767.77 | AT16: 6163.8275 | AU16: 5574.7186 | AV16: 5034.1764 | AW16: 7045.1706 | AX16: 8734.5694 | AY16: 8992.8929 | AZ16: 9371.7302 | BA16: 9861.279 | BB16: 8458.741 | BC16: 6345.0609 | BD16: 5214.9279 | BE16: 5016.03 | BF16: 5773.85 | BG16: 5436.3115 | BH16: 5786.2898 | BI16: 6832.0386 | BJ16: 6947.7562 | BK16: 6817.7986 | BL16: 9084.7446 | BM16: 8619.9207 | BN16: 9210.0008 | BO16: 9914.5039 | BP16: 10065 | BQ16: 8821.0377 | BR16: 9317.3747 | BS16: 12673 | BT16: 12030.227 | BU16: 13946.34 | BV16: 15660.952 | BW16: 17477.135 | BX16: 19011 | BY16: 18226.272 | BZ16: 17364.203 | CA16: 18264 | CB16: 17301 | CC16: 16639.141 | CD16: 17027 | CE16: 16827.058 | CF16: 16828.264 | CH16: =Sheet1!CH16-[1]Sheet1!CH16 -> #ERROR! | CI16: =Sheet1!CI16-[1]Sheet1!CI16 -> #ERROR! | CJ16: =Sheet1!CJ16-[1]Sheet1!CJ16 -> #ERROR! | CK16: =Sheet1!CK16-[1]Sheet1!CK16 -> #ERROR! | CL16: =Sheet1!CL16-[1]Sheet1!CL16 -> #ERROR! | CM16: =Sheet1!CM16-[1]Sheet1!CM16 -> #ERROR! | CN16: =Sheet1!CN16-[1]Sheet1!CN16 -> #ERROR! | CO16: =Sheet1!CO16-[1]Sheet1!CO16 -> #ERROR!
B17: Average grade in ore mined | C17: g/t | F17: 4.169786 | G17: 1.7677485 | H17: 2.5018847 | I17: 2.4118227 | J17: 2.4247284 | K17: 2.3677328 | L17: 2.3800896 | M17: 2.0131631 | N17: 1.8714069 | O17: 2.3559662 | P17: 2.4553028 | Q17: 2.3780405 | R17: =Sheet1!R17-[1]Sheet1!R17 -> #ERROR! | S17: =Sheet1!S17-[1]Sheet1!S17 -> #ERROR! | T17: =Sheet1!T17-[1]Sheet1!T17 -> #ERROR! | U17: =Sheet1!U17-[1]Sheet1!U17 -> #ERROR! | V17: =Sheet1!V17-[1]Sheet1!V17 -> #ERROR! | W17: =Sheet1!W17-[1]Sheet1!W17 -> #ERROR! | Y17: 5.7611311 | Z17: 3.4759562 | AA17: 3.2726575 | AB17: 2.5739761 | AC17: 1.9044679 | AD17: 1.8424614 | AE17: 1.6742049 | AF17: 1.649931 | AG17: 1.9494346 | AH17: 2.2961402 | AI17: 2.858787 | AJ17: 2.6131435 | AK17: 2.5403213 | AL17: 2.2832983 | AM17: 2.3209962 | AN17: 2.4979716 | AO17: 2.4226242 | AP17: 2.3207251 | AQ17: 2.4187264 | AR17: 2.5393219 | AS17: 2.473379 | AT17: 2.4117756 | AU17: 2.2935633 | AV17: 2.2539133 | AW17: 2.2793029 | AX17: 2.474296 | AY17: 2.3826513 | AZ17: 2.3655962 | BA17: 2.3149365 | BB17: 2.0782288 | BC17: 1.7140387 | BD17: 1.7009284 | BE17: 1.8444524 | BF17: 1.8872743 | BG17: 1.815472 | BH17: 1.9314917 | BI17: 2.0802787 | BJ17: 2.3108874 | BK17: 2.3430781 | BL17: 2.6074397 | BM17: 2.5365385 | BN17: 2.4930213 | BO17: 2.4438756 | BP17: 2.3611575 | BQ17: 2.4330593 | BR17: 2.4380291 | BS17: 2.3126105 | BT17: 2.360159 | BU17: 2.0599898 | BV17: 2.1072902 | BW17: 1.9001312 | BX17: 1.7750233 | BY17: 1.7021282 | BZ17: 1.8670152 | CA17: 1.7844092 | CB17: 1.7087818 | CC17: 1.714072 | CD17: 1.7834139 | CE17: 1.4735217 | CF17: 1.5611348 | CH17: =Sheet1!CH17-[1]Sheet1!CH17 -> #ERROR! | CI17: =Sheet1!CI17-[1]Sheet1!CI17 -> #ERROR! | CJ17: =Sheet1!CJ17-[1]Sheet1!CJ17 -> #ERROR! | CK17: =Sheet1!CK17-[1]Sheet1!CK17 -> #ERROR! | CL17: =Sheet1!CL17-[1]Sheet1!CL17 -> #ERROR! | CM17: =Sheet1!CM17-[1]Sheet1!CM17 -> #ERROR! | CN17: =Sheet1!CN17-[1]Sheet1!CN17 -> #ERROR! | CO17: =Sheet1!CO17-[1]Sheet1!CO17 -> #ERROR!
B19: Processing
B20: Ore processed | C20: kT | F20: 10518.569 | G20: 10814.122 | H20: 13930.592 | I20: 18230.309 | J20: 20160.756 | K20: 21757.982 | L20: 22481 | M20: 23743 | N20: 24823 | O20: 26445 | P20: 28663.272 | Q20: 38024.578 | R20: =Sheet1!R20-[1]Sheet1!R20 -> #ERROR! | S20: =Sheet1!S20-[1]Sheet1!S20 -> #ERROR! | T20: =Sheet1!T20-[1]Sheet1!T20 -> #ERROR! | U20: =Sheet1!U20-[1]Sheet1!U20 -> #ERROR! | V20: =Sheet1!V20-[1]Sheet1!V20 -> #ERROR! | W20: =Sheet1!W20-[1]Sheet1!W20 -> #ERROR! | Y20: 2226.6816 | Z20: 2386.865 | AA20: 3071.4328 | AB20: 2833.5897 | AC20: 2143.549 | AD20: 2850.262 | AE20: 2694.541 | AF20: 3125.77 | AG20: 3319.5813 | AH20: 3318.205 | AI20: 3402.001 | AJ20: 3890.805 | AK20: 3848.13 | AL20: 4645.6 | AM20: 4807.34 | AN20: 4929.239 | AO20: 5081.621 | AP20: 4806.623 | AQ20: 5191.855 | AR20: 5080.657 | AS20: 5248.8818 | AT20: 5141.101 | AU20: 5590.378 | AV20: 5777.621 | AW20: 5280 | AX20: 5680 | AY20: 5776 | AZ20: 5745 | BA20: 5633 | BB20: 6016 | BC20: 6053 | BD20: 6041 | BE20: 5978 | BF20: 6143 | BG20: 6322 | BH20: 6380 | BI20: 6396 | BJ20: 6535 | BK20: 6521 | BL20: 6993 | BM20: 6630 | BN20: 6925 | BO20: 7299.2724 | BP20: 7809 | BQ20: 8491.7653 | BR20: 9872 | BS20: 10382 | BT20: 9278.7121 | BU20: 10283.953 | BV20: 10900.821 | BW20: 11366.088 | BX20: 11527 | BY20: 10698.374 | BZ20: 11753 | CA20: 12224 | CB20: 10438 | CC20: 11126.002 | CD20: 12169 | CE20: 12722 | CF20: 11878 | CH20: =Sheet1!CH20-[1]Sheet1!CH20 -> #ERROR! | CI20: =Sheet1!CI20-[1]Sheet1!CI20 -> #ERROR! | CJ20: =Sheet1!CJ20-[1]Sheet1!CJ20 -> #ERROR! | CK20: =Sheet1!CK20-[1]Sheet1!CK20 -> #ERROR! | CL20: =Sheet1!CL20-[1]Sheet1!CL20 -> #ERROR! | CM20: =Sheet1!CM20-[1]Sheet1!CM20 -> #ERROR! | CN20: =Sheet1!CN20-[1]Sheet1!CN20 -> #ERROR! | CO20: =Sheet1!CO20-[1]Sheet1!CO20 -> #ERROR!
B21: Average grade in ore processed | C21: g/t | F21: 3.6381165 | G21: 3.7090189 | H21: 3.1589391 | I21: 2.6151055 | J21: 2.4918542 | K21: 2.4753478 | L21: 2.4911036 | M21: 2.51412 | N21: 2.428159 | O21: 2.5402635 | P21: 2.698494 | Q21: 2.404956 | R21: =Sheet1!R21-[1]Sheet1!R21 -> #ERROR! | S21: =Sheet1!S21-[1]Sheet1!S21 -> #ERROR! | T21: =Sheet1!T21-[1]Sheet1!T21 -> #ERROR! | U21: =Sheet1!U21-[1]Sheet1!U21 -> #ERROR! | V21: =Sheet1!V21-[1]Sheet1!V21 -> #ERROR! | W21: =Sheet1!W21-[1]Sheet1!W21 -> #ERROR! | Y21: 3.411417 | Z21: 3.5927865 | AA21: 3.671789 | AB21: 3.8179454 | AC21: 3.3743623 | AD21: 4.6143915 | AE21: 3.450402 | AF21: 3.3358813 | AG21: 3.0527334 | AH21: 3.1424766 | AI21: 3.676075 | AJ21: 2.8114242 | AK21: 2.5530466 | AL21: 2.5755923 | AM21: 2.6161662 | AN21: 2.6997583 | AO21: 2.4932009 | AP21: 2.4192634 | AQ21: 2.4601472 | AR21: 2.5915835 | AS21: 2.4838084 | AT21: 2.5099231 | AU21: 2.4183859 | AV21: 2.4920113 | AW21: 2.4774749 | AX21: 2.472836 | AY21: 2.5444179 | AZ21: 2.4680881 | BA21: 2.4669507 | BB21: 2.5103353 | BC21: 2.5022045 | BD21: 2.573812 | BE21: 2.4313944 | BF21: 2.5325774 | BG21: 2.3693281 | BH21: 2.3828841 | BI21: 2.3902954 | BJ21: 2.3564058 | BK21: 2.5760735 | BL21: 2.8158516 | BM21: 2.5778287 | BN21: 2.6975835 | BO21: 2.8445642 | BP21: 2.6521273 | BQ21: 2.5206099 | BR21: 2.3668405 | BS21: 2.32 | BT21: 2.4300066 | BU21: 2.4108559 | BV21: 2.3593021 | BW21: 2.2995297 | BX21: 2.3997457 | BY21: 2.1996022 | BZ21: 2.24 | CA21: 2.25 | CB21: 2.3052993 | CC21: 2.1778314 | CD21: 2.1 | CE21: 2.1 | CF21: 2.12 | CH21: =Sheet1!CH21-[1]Sheet1!CH21 -> #ERROR! | CI21: =Sheet1!CI21-[1]Sheet1!CI21 -> #ERROR! | CJ21: =Sheet1!CJ21-[1]Sheet1!CJ21 -> #ERROR! | CK21: =Sheet1!CK21-[1]Sheet1!CK21 -> #ERROR! | CL21: =Sheet1!CL21-[1]Sheet1!CL21 -> #ERROR! | CM21: =Sheet1!CM21-[1]Sheet1!CM21 -> #ERROR! | CN21: =Sheet1!CN21-[1]Sheet1!CN21 -> #ERROR! | CO21: =Sheet1!CO21-[1]Sheet1!CO21 -> #ERROR!
B22: Recovery | C22: % | F22: 0.84677869 | G22: 0.82287174 | H22: 0.74946314 | I22: 0.71883009 | J22: 0.76104718 | K22: 0.78543865 | L22: 0.78992988 | M22: 0.81017695 | N22: 0.83713884 | O22: 0.83886561 | P22: 0.834 | Q22: 0.808 | R22: =Sheet1!R22-[1]Sheet1!R22 -> #ERROR! | S22: =Sheet1!S22-[1]Sheet1!S22 -> #ERROR! | T22: =Sheet1!T22-[1]Sheet1!T22 -> #ERROR! | U22: =Sheet1!U22-[1]Sheet1!U22 -> #ERROR! | V22: =Sheet1!V22-[1]Sheet1!V22 -> #ERROR! | W22: =Sheet1!W22-[1]Sheet1!W22 -> #ERROR! | Y22: 0.88739155 | Z22: 0.8799866 | AA22: 0.82707102 | AB22: 0.81006945 | AC22: 0.77034386 | AD22: 0.85182169 | AE22: 0.82717298 | AF22: 0.82613108 | AG22: 0.78620145 | AH22: 0.747825 | AI22: 0.77439939 | AJ22: 0.68540599 | AK22: 0.66900775 | AL22: 0.70541011 | AM22: 0.74750146 | AN22: 0.73676721 | AO22: 0.76378615 | AP22: 0.7826639 | AQ22: 0.735753 | AR22: 0.76132582 | AS22: 0.78699789 | AT22: 0.81514248 | AU22: 0.76328692 | AV22: 0.77917219 | AW22: 0.78538079 | AX22: 0.79236407 | AY22: 0.78360431 | AZ22: 0.79827176 | BA22: 0.79981049 | BB22: 0.80895623 | BC22: 0.81330927 | BD22: 0.81757641 | BE22: 0.82618322 | BF22: 0.83267609 | BG22: 0.85100815 | BH22: 0.83851498 | BI22: 0.84043301 | BJ22: 0.84217616 | BK22: 0.84327287 | BL22: 0.83129991 | BM22: 0.83282921 | BN22: 0.83938412 | BO22: 0.838 | BP22: 0.827 | BQ22: 0.815 | BR22: 0.80623953 | BS22: 0.80575463 | BT22: 0.80610257 | BU22: 0.81406295 | BV22: 0.81790807 | BW22: 0.82145667 | BX22: 0.832 | BY22: 0.83581612 | BZ22: 0.83404487 | CA22: 0.84115123 | CB22: 0.83882127 | CC22: 0.81634021 | CD22: 0.82596919 | CE22: 0.82978908 | CF22: 0.834 | CH22: =Sheet1!CH22-[1]Sheet1!CH22 -> #ERROR! | CI22: =Sheet1!CI22-[1]Sheet1!CI22 -> #ERROR! | CJ22: =Sheet1!CJ22-[1]Sheet1!CJ22 -> #ERROR! | CK22: =Sheet1!CK22-[1]Sheet1!CK22 -> #ERROR! | CL22: =Sheet1!CL22-[1]Sheet1!CL22 -> #ERROR! | CM22: =Sheet1!CM22-[1]Sheet1!CM22 -> #ERROR! | CN22: =Sheet1!CN22-[1]Sheet1!CN22 -> #ERROR! | CO22: =Sheet1!CO22-[1]Sheet1!CO22 -> #ERROR!
